Workbook

Sheet fd_domain_list
A1: pCWID | B1: name | C1: Type | D1: n_id | E1: c_id | F1: n_c_id | G1: Description | H1: n_domain | I1: c_domain | J1: n_c_domain | K1: Expectation | L1: Epistasis
A2: pCW18 | B2: pCW18 pHR-UCOE-SFFV-N34-dCas9-C32-P2a-mNeonGreen | C2: Domain construct | D2: =MID(B2, SEARCH("SFFV-", B2) + LEN("SFFV-"), SEARCH("-dCas9-", B2) - SEARCH("SFFV-", B2) - LEN("SFFV-")) -> N34 | E2: =MID(B2, SEARCH("-dCas9-", B2) + LEN("-dCas9-"), SEARCH("-P2a-mNeonGreen", B2) - SEARCH("-dCas9-", B2) - LEN("-dCas9-")) -> C32 | F2: =CONCATENATE(D2,"_",E2) -> N34_C32 | G2: DNMT3A_3L-KRAB | H2: =VLOOKUP(D2, domain_ref!C:F, 4, FALSE) -> DNMT3A-3L_JKNp112 | I2: =VLOOKUP(E2, domain_ref!D:F, 3, FALSE) -> Gilbert_Lab_CRISPRi_KRAB | J2: =CONCATENATE(H2,"_",I2) -> DNMT3A-3L_JKNp112_Gilbert_Lab_CRISPRi_KRAB | K2: Repression | L2: N
A3: pCW24 | B3: pCW24 pCWT SFFV-N282-XTEN16-2XNLS-dCas9-XTEN80-C346-IRES-Puro-P2A-mNeonGreen | C3: Domain construct | D3: =MID(B3, SEARCH("SFFV-", B3) + LEN("SFFV-"), SEARCH("-XTEN16-", B3) - SEARCH("SFFV-", B3) - LEN("SFFV-")) -> N282 | E3: =MID(B3, SEARCH("-XTEN80-", B3) + LEN("-XTEN80-"), SEARCH("-IRES-Puro-P2A-mNeonGreen", B3) - SEARCH("-XTEN80-", B3) - LEN("-XTEN80-")) -> C346 | F3: =CONCATENATE(D3,"_",E3) -> N282_C346 | G3: VP160-MSX2 | H3: =VLOOKUP(D3, domain_ref!C:F, 4, FALSE) -> VP160 | I3: =VLOOKUP(E3, domain_ref!D:F, 3, FALSE) -> MSX2_HUMAN | J3: =CONCATENATE(H3,"_",I3) -> VP160_MSX2_HUMAN | K3: Activation | L3: N
A4: pCW25 | B4: pCW25 pCWT SFFV-N284-XTEN16-2XNLS-dCas9-XTEN80-C267-IRES-Puro-P2A-mNeonGreen | C4: Domain construct | D4: =MID(B4, SEARCH("SFFV-", B4) + LEN("SFFV-"), SEARCH("-XTEN16-", B4) - SEARCH("SFFV-", B4) - LEN("SFFV-")) -> N284 | E4: =MID(B4, SEARCH("-XTEN80-", B4) + LEN("-XTEN80-"), SEARCH("-IRES-Puro-P2A-mNeonGreen", B4) - SEARCH("-XTEN80-", B4) - LEN("-XTEN80-")) -> C267 | F4: =CONCATENATE(D4,"_",E4) -> N284_C267 | G4: p65 HSF1-FOXA1-Nterm | H4: =VLOOKUP(D4, domain_ref!C:F, 4, FALSE) -> p65-HSF1 | I4: =VLOOKUP(E4, domain_ref!D:F, 3, FALSE) -> FOXA1-Nterm | J4: =CONCATENATE(H4,"_",I4) -> p65-HSF1_FOXA1-Nterm | K4: Activation | L4: N
A5: pCW26 | B5: pCW26 pCWT SFFV-N284-XTEN16-2XNLS-dCas9-XTEN80-C257-IRES-Puro-P2A-mNeonGreen | C5: Domain construct | D5: =MID(B5, SEARCH("SFFV-", B5) + LEN("SFFV-"), SEARCH("-XTEN16-", B5) - SEARCH("SFFV-", B5) - LEN("SFFV-")) -> N284 | E5: =MID(B5, SEARCH("-XTEN80-", B5) + LEN("-XTEN80-"), SEARCH("-IRES-Puro-P2A-mNeonGreen", B5) - SEARCH("-XTEN80-", B5) - LEN("-XTEN80-")) -> C257 | F5: =CONCATENATE(D5,"_",E5) -> N284_C257 | G5: p65 HSF1-c-Myb-TAD | H5: =VLOOKUP(D5, domain_ref!C:F, 4, FALSE) -> p65-HSF1 | I5: =VLOOKUP(E5, domain_ref!D:F, 3, FALSE) -> c-Myb-TAD | J5: =CONCATENATE(H5,"_",I5) -> p65-HSF1_c-Myb-TAD | K5: Activation | L5: N
A6: pCW28 | B6: pCW28 pCWT SFFV-N313-XTEN16-2XNLS-dCas9-XTEN80-C306-IRES-Puro-P2A-mNeonGreen | C6: Domain construct | D6: =MID(B6, SEARCH("SFFV-", B6) + LEN("SFFV-"), SEARCH("-XTEN16-", B6) - SEARCH("SFFV-", B6) - LEN("SFFV-")) -> N313 | E6: =MID(B6, SEARCH("-XTEN80-", B6) + LEN("-XTEN80-"), SEARCH("-IRES-Puro-P2A-mNeonGreen", B6) - SEARCH("-XTEN80-", B6) - LEN("-XTEN80-")) -> C306 | F6: =CONCATENATE(D6,"_",E6) -> N313_C306 | G6: SaII-CobB | H6: =VLOOKUP(D6, domain_ref!C:F, 4, FALSE) -> SaII | I6: =VLOOKUP(E6, domain_ref!D:F, 3, FALSE) -> CobB | J6: =CONCATENATE(H6,"_",I6) -> SaII_CobB | K6: Repression | L6: N
A7: pCW31 | B7: pCW31 pCWT SFFV-RC433-XTEN16-2XNLS-dCas9-XTEN80-RC433-IRES-Puro-P2A-mNeonGreen | C7: Domain construct | D7: =MID(B7, SEARCH("SFFV-", B7) + LEN("SFFV-"), SEARCH("-XTEN16-", B7) - SEARCH("SFFV-", B7) - LEN("SFFV-")) -> RC433 | E7: =MID(B7, SEARCH("-XTEN80-", B7) + LEN("-XTEN80-"), SEARCH("-IRES-Puro-P2A-mNeonGreen", B7) - SEARCH("-XTEN80-", B7) - LEN("-XTEN80-")) -> RC433 | F7: =CONCATENATE(D7,"_",E7) -> RC433_RC433 | G7: Random-Random | H7: =VLOOKUP(D7, domain_ref!C:F, 4, FALSE) -> RC433 | I7: =VLOOKUP(E7, domain_ref!D:F, 3, FALSE) -> RC433 | J7: =CONCATENATE(H7,"_",I7) -> RC433_RC433 | K7: Control | L7: N
A8: pCW33 | B8: pCW33 pCWT SFFV-N282-XTEN16-2XNLS-dCas9-XTEN80-C285-IRES-Puro-P2A-mNeonGreen | C8: Domain construct | D8: =MID(B8, SEARCH("SFFV-", B8) + LEN("SFFV-"), SEARCH("-XTEN16-", B8) - SEARCH("SFFV-", B8) - LEN("SFFV-")) -> N282 | E8: =MID(B8, SEARCH("-XTEN80-", B8) + LEN("-XTEN80-"), SEARCH("-IRES-Puro-P2A-mNeonGreen", B8) - SEARCH("-XTEN80-", B8) - LEN("-XTEN80-")) -> C285 | F8: =CONCATENATE(D8,"_",E8) -> N282_C285 | G8: VP160-p65-MyoD | H8: =VLOOKUP(D8, domain_ref!C:F, 4, FALSE) -> VP160 | I8: =VLOOKUP(E8, domain_ref!D:F, 3, FALSE) -> p65-MyoD | J8: =CONCATENATE(H8,"_",I8) -> VP160_p65-MyoD | K8: Activation | L8: N
B9: SFFV-N246-XTEN16-2XNLS-dCas9-XTEN80-C239-IRES-Puro-P2A-mNeonGreen | C9: Domain construct | D9: =MID(B9, SEARCH("SFFV-", B9) + LEN("SFFV-"), SEARCH("-XTEN16-", B9) - SEARCH("SFFV-", B9) - LEN("SFFV-")) -> N246 | E9: =MID(B9, SEARCH("-XTEN80-", B9) + LEN("-XTEN80-"), SEARCH("-IRES-Puro-P2A-mNeonGreen", B9) - SEARCH("-XTEN80-", B9) - LEN("-XTEN80-")) -> C239 | F9: =CONCATENATE(D9,"_",E9) -> N246_C239 | H9: =VLOOKUP(D9, domain_ref!C:F, 4, FALSE) -> ATRX_HUMAN | I9: =VLOOKUP(E9, domain_ref!D:F, 3, FALSE) -> KDM8_HUMAN | J9: =CONCATENATE(H9,"_",I9) -> ATRX_HUMAN_KDM8_HUMAN
A10: pCW41 | B10: pCW41 pCWT SFFV-RC433-XTEN16-2XNLS-dCas9-XTEN80-C267-IRES-Puro-P2A-mNeonGreen | C10: Domain construct | D10: =MID(B10, SEARCH("SFFV-", B10) + LEN("SFFV-"), SEARCH("-XTEN16-", B10) - SEARCH("SFFV-", B10) - LEN("SFFV-")) -> RC433 | E10: =MID(B10, SEARCH("-XTEN80-", B10) + LEN("-XTEN80-"), SEARCH("-IRES-Puro-P2A-mNeonGreen", B10) - SEARCH("-XTEN80-", B10) - LEN("-XTEN80-")) -> C267 | F10: =CONCATENATE(D10,"_",E10) -> RC433_C267 | G10: RC433-FOXA1-Nterm | H10: =VLOOKUP(D10, domain_ref!C:F, 4, FALSE) -> RC433 | I10: =VLOOKUP(E10, domain_ref!D:F, 3, FALSE) -> FOXA1-Nterm | J10: =CONCATENATE(H10,"_",I10) -> RC433_FOXA1-Nterm | K10: Activation | L10: N
A11: pCW49 | B11: pCW49 pCWT SFFV-N281-XTEN16-2XNLS-dCas9-XTEN80-RC433-IRES-Puro-P2A-mNeonGreen | C11: Domain construct | D11: =MID(B11, SEARCH("SFFV-", B11) + LEN("SFFV-"), SEARCH("-XTEN16-", B11) - SEARCH("SFFV-", B11) - LEN("SFFV-")) -> N281 | E11: =MID(B11, SEARCH("-XTEN80-", B11) + LEN("-XTEN80-"), SEARCH("-IRES-Puro-P2A-mNeonGreen", B11) - SEARCH("-XTEN80-", B11) - LEN("-XTEN80-")) -> RC433 | F11: =CONCATENATE(D11,"_",E11) -> N281_RC433 | G11: VP64-RC433 | H11: =VLOOKUP(D11, domain_ref!C:F, 4, FALSE) -> VP64 | I11: =VLOOKUP(E11, domain_ref!D:F, 3, FALSE) -> RC433 | J11: =CONCATENATE(H11,"_",I11) -> VP64_RC433 | K11: Activation | L11: N
A12: pCW63 | B12: pCW63 pCWT SFFV-N218-XTEN16-2XNLS-dCas9-XTEN80-C280-IRES-Puro-P2A-mNeonGreen | C12: Domain construct | D12: =MID(B12, SEARCH("SFFV-", B12) + LEN("SFFV-"), SEARCH("-XTEN16-", B12) - SEARCH("SFFV-", B12) - LEN("SFFV-")) -> N218 | E12: =MID(B12, SEARCH("-XTEN80-", B12) + LEN("-XTEN80-"), SEARCH("-IRES-Puro-P2A-mNeonGreen", B12) - SEARCH("-XTEN80-", B12) - LEN("-XTEN80-")) -> C280 | F12: =CONCATENATE(D12,"_",E12) -> N218_C280 | G12: IN80B_HUMAN-CBF1-Cterm | H12: =VLOOKUP(D12, domain_ref!C:F, 4, FALSE) -> IN80B_HUMAN | I12: =VLOOKUP(E12, domain_ref!D:F, 3, FALSE) -> CBF1-Cterm | J12: =CONCATENATE(H12,"_",I12) -> IN80B_HUMAN_CBF1-Cterm | K12: Activation | L12: N
A13: pCW65 | B13: pCW65 pCWT SFFV-N131-XTEN16-2XNLS-dCas9-XTEN80-C185-IRES-Puro-P2A-mNeonGreen | C13: Domain construct | D13: =MID(B13, SEARCH("SFFV-", B13) + LEN("SFFV-"), SEARCH("-XTEN16-", B13) - SEARCH("SFFV-", B13) - LEN("SFFV-")) -> N131 | E13: =MID(B13, SEARCH("-XTEN80-", B13) + LEN("-XTEN80-"), SEARCH("-IRES-Puro-P2A-mNeonGreen", B13) - SEARCH("-XTEN80-", B13) - LEN("-XTEN80-")) -> C185 | F13: =CONCATENATE(D13,"_",E13) -> N131_C185 | G13: PRDM2_HUMAN-RBBP7_HUMAN | H13: =VLOOKUP(D13, domain_ref!C:F, 4, FALSE) -> PRDM2_HUMAN | I13: =VLOOKUP(E13, domain_ref!D:F, 3, FALSE) -> RBBP7_HUMAN | J13: =CONCATENATE(H13,"_",I13) -> PRDM2_HUMAN_RBBP7_HUMAN | K13: Repression | L13: N
A14: pCW84 | B14: pCW84 pCWT SFFV-RC433-XTEN16-2XNLS-dCas9-XTEN80-C32-IRES-Puro-P2A-mNeonGreen | C14: Domain construct | D14: =MID(B14, SEARCH("SFFV-", B14) + LEN("SFFV-"), SEARCH("-XTEN16-", B14) - SEARCH("SFFV-", B14) - LEN("SFFV-")) -> RC433 | E14: =MID(B14, SEARCH("-XTEN80-", B14) + LEN("-XTEN80-"), SEARCH("-IRES-Puro-P2A-mNeonGreen", B14) - SEARCH("-XTEN80-", B14) - LEN("-XTEN80-")) -> C32 | F14: =CONCATENATE(D14,"_",E14) -> RC433_C32 | G14: RC433-KRAB | H14: =VLOOKUP(D14, domain_ref!C:F, 4, FALSE) -> RC433 | I14: =VLOOKUP(E14, domain_ref!D:F, 3, FALSE) -> Gilbert_Lab_CRISPRi_KRAB | J14: =CONCATENATE(H14,"_",I14) -> RC433_Gilbert_Lab_CRISPRi_KRAB | K14: Repression | L14: N
A15: pCW73 | B15: pCW73 pCWT SFFV-N105-XTEN16-2XNLS-dCas9-XTEN80-C131-IRES-Puro-P2A-mNeonGreen | C15: Domain construct | D15: =MID(B15, SEARCH("SFFV-", B15) + LEN("SFFV-"), SEARCH("-XTEN16-", B15) - SEARCH("SFFV-", B15) - LEN("SFFV-")) -> N105 | E15: =MID(B15, SEARCH("-XTEN80-", B15) + LEN("-XTEN80-"), SEARCH("-IRES-Puro-P2A-mNeonGreen", B15) - SEARCH("-XTEN80-", B15) - LEN("-XTEN80-")) -> C131 | F15: =CONCATENATE(D15,"_",E15) -> N105_C131 | G15: MBD2_HUMAN-PRDM2_HUMAN | H15: =VLOOKUP(D15, domain_ref!C:F, 4, FALSE) -> MBD2_HUMAN | I15: =VLOOKUP(E15, domain_ref!D:F, 3, FALSE) -> PRDM2_HUMAN | J15: =CONCATENATE(H15,"_",I15) -> MBD2_HUMAN_PRDM2_HUMAN | K15: shrug emoji | L15: N
A16: pCW59 | B16: pCW59 pCWT SFFV-N252-XTEN16-2XNLS-dCas9-XTEN80-C46-IRES-Puro-P2A-mNeonGreen | C16: Domain construct | D16: =MID(B16, SEARCH("SFFV-", B16) + LEN("SFFV-"), SEARCH("-XTEN16-", B16) - SEARCH("SFFV-", B16) - LEN("SFFV-")) -> N252 | E16: =MID(B16, SEARCH("-XTEN80-", B16) + LEN("-XTEN80-"), SEARCH("-IRES-Puro-P2A-mNeonGreen", B16) - SEARCH("-XTEN80-", B16) - LEN("-XTEN80-")) -> C46 | F16: =CONCATENATE(D16,"_",E16) -> N252_C46 | G16: HCFC1-SMRD1 | H16: =VLOOKUP(D16, domain_ref!C:F, 4, FALSE) -> HCFC1_HUMAN | I16: =VLOOKUP(E16, domain_ref!D:F, 3, FALSE) -> SMRD1_HUMAN | J16: =CONCATENATE(H16,"_",I16) -> HCFC1_HUMAN_SMRD1_HUMAN | K16: shrug emoji | L16: Y
A17: pCW78 | B17: pCW78 pCWT SFFV-N252-XTEN16-2XNLS-dCas9-XTEN80-RC433-IRES-Puro-P2A-mNeonGreen | C17: Domain construct | D17: =MID(B17, SEARCH("SFFV-", B17) + LEN("SFFV-"), SEARCH("-XTEN16-", B17) - SEARCH("SFFV-", B17) - LEN("SFFV-")) -> N252 | E17: =MID(B17, SEARCH("-XTEN80-", B17) + LEN("-XTEN80-"), SEARCH("-IRES-Puro-P2A-mNeonGreen", B17) - SEARCH("-XTEN80-", B17) - LEN("-XTEN80-")) -> RC433 | F17: =CONCATENATE(D17,"_",E17) -> N252_RC433 | G17: HCFC1-RC433 | H17: =VLOOKUP(D17, domain_ref!C:F, 4, FALSE) -> HCFC1_HUMAN | I17: =VLOOKUP(E17, domain_ref!D:F, 3, FALSE) -> RC433 | J17: =CONCATENATE(H17,"_",I17) -> HCFC1_HUMAN_RC433 | K17: shrug emoji | L17: Y
A18: pCW82 | B18: pCW82 pCWT SFFV-RC433-XTEN16-2XNLS-dCas9-XTEN80-C46-IRES-Puro-P2A-mNeonGreen | C18: Domain construct | D18: =MID(B18, SEARCH("SFFV-", B18) + LEN("SFFV-"), SEARCH("-XTEN16-", B18) - SEARCH("SFFV-", B18) - LEN("SFFV-")) -> RC433 | E18: =MID(B18, SEARCH("-XTEN80-", B18) + LEN("-XTEN80-"), SEARCH("-IRES-Puro-P2A-mNeonGreen", B18) - SEARCH("-XTEN80-", B18) - LEN("-XTEN80-")) -> C46 | F18: =CONCATENATE(D18,"_",E18) -> RC433_C46 | G18: RC433-SMRD! | H18: =VLOOKUP(D18, domain_ref!C:F, 4, FALSE) -> RC433 | I18: =VLOOKUP(E18, domain_ref!D:F, 3, FALSE) -> SMRD1_HUMAN | J18: =CONCATENATE(H18,"_",I18) -> RC433_SMRD1_HUMAN | K18: shrug emoji | L18: Y
A19: pCW47 | B19: pCW47 pCWT SFFV-N105-XTEN16-2XNLS-dCas9-XTEN80-RC433-IRES-Puro-P2A-mNeonGreen | C19: Domain construct | D19: =MID(B19, SEARCH("SFFV-", B19) + LEN("SFFV-"), SEARCH("-XTEN16-", B19) - SEARCH("SFFV-", B19) - LEN("SFFV-")) -> N105 | E19: =MID(B19, SEARCH("-XTEN80-", B19) + LEN("-XTEN80-"), SEARCH("-IRES-Puro-P2A-mNeonGreen", B19) - SEARCH("-XTEN80-", B19) - LEN("-XTEN80-")) -> RC433 | F19: =CONCATENATE(D19,"_",E19) -> N105_RC433 | G19: MBD2_HUMAN-RC433 | H19: =VLOOKUP(D19, domain_ref!C:F, 4, FALSE) -> MBD2_HUMAN | I19: =VLOOKUP(E19, domain_ref!D:F, 3, FALSE) -> RC433 | J19: =CONCATENATE(H19,"_",I19) -> MBD2_HUMAN_RC433 | K19: shrug emoji | L19: Y
A20: pCW79 | B20: pCW79 pCWT SFFV-RC433-XTEN16-2XNLS-dCas9-XTEN80-C131-IRES-Puro-P2A-mNeonGreen | C20: Domain construct | D20: =MID(B20, SEARCH("SFFV-", B20) + LEN("SFFV-"), SEARCH("-XTEN16-", B20) - SEARCH("SFFV-", B20) - LEN("SFFV-")) -> RC433 | E20: =MID(B20, SEARCH("-XTEN80-", B20) + LEN("-XTEN80-"), SEARCH("-IRES-Puro-P2A-mNeonGreen", B20) - SEARCH("-XTEN80-", B20) - LEN("-XTEN80-")) -> C131 | F20: =CONCATENATE(D20,"_",E20) -> RC433_C131 | G20: RC433-PRDM2 | H20: =VLOOKUP(D20, domain_ref!C:F, 4, FALSE) -> RC433 | I20: =VLOOKUP(E20, domain_ref!D:F, 3, FALSE) -> PRDM2_HUMAN | J20: =CONCATENATE(H20,"_",I20) -> RC433_PRDM2_HUMAN | K20: shrug emoji | L20: Y
B21: SFFV-N111-XTEN16-2XNLS-dCas9-XTEN80-C278-IRES-Puro-P2A-mNeonGreen | C21: Domain construct | D21: =MID(B21, SEARCH("SFFV-", B21) + LEN("SFFV-"), SEARCH("-XTEN16-", B21) - SEARCH("SFFV-", B21) - LEN("SFFV-")) -> N111 | E21: =MID(B21, SEARCH("-XTEN80-", B21) + LEN("-XTEN80-"), SEARCH("-IRES-Puro-P2A-mNeonGreen", B21) - SEARCH("-XTEN80-", B21) - LEN("-XTEN80-")) -> C278 | F21: =CONCATENATE(D21,"_",E21) -> N111_C278 | H21: =VLOOKUP(D21, domain_ref!C:F, 4, FALSE) -> KDM5A_HUMAN | I21: =VLOOKUP(E21, domain_ref!D:F, 3, FALSE) -> TET2CD | J21: =CONCATENATE(H21,"_",I21) -> KDM5A_HUMAN_TET2CD

Sheet domain_ref
A1: Library | B1: DomainID | C1: N_DomainID | D1: C_DomainID | E1: UniprotID (when applicable) | F1: Gene name | G1: Reference (when applicable)
A2: Lib1, Lib2 | B2: 1 | C2: N1 | D2: C1 | E2: O15047 | F2: SETD1A
A3: Lib1, Lib2 | B3: 2 | C3: N2 | D3: C2 | E3: O15047 | F3: SETD1A
A4: Lib1, Lib2 | B4: 3 | C4: N3 | D4: C3 | E4: O15379 | F4: HDAC3 | H4: =MEDIAN(#REF!) -> #REF!
A5: Lib1, Lib2 | B5: 4 | C5: N4 | D5: C4 | E5: O15550 | F5: KDM6A | G5: non-recoded
A6: Lib1, Lib2 | B6: 5 | C6: N5 | D6: C5 | E6: O60341 | F6: KDM1A
A7: Lib1, Lib2 | B7: 6 | C7: N6 | D7: C6 | E7: O60341 | F7: KDM1A
A8: Lib1, Lib2 | B8: 7 | C8: N7 | D8: C7 | E8: P21506 | F8: ZNF10
A9: Lib1, Lib2 | B9: 8 | C9: N8 | D9: C8 | E9: P51608 | F9: MECP2
A10: Lib1, Lib2 | B10: 9 | C10: N9 | D10: C9 | E10: P51608 | F10: MECP2
A11: Lib1, Lib2 | B11: 10 | C11: N10 | D11: C10 | E11: Q00613 | F11: HSF1
A12: Lib1, Lib2 | B12: 11 | C12: N11 | D12: C11 | E12: Q03164 | F12: KMT2A
A13: Lib1, Lib2 | B13: 12 | C13: N12 | D13: C12 | E13: Q03164 | F13: KMT2A
A14: Lib1, Lib2 | B14: 14 | C14: N14 | D14: C14 | E14: Q04206 | F14: RELA
A15: Lib1, Lib2 | B15: 15 | C15: N15 | D15: C15 | E15: Q09472 | F15: EP300
A16: Lib1, Lib2 | B16: 16 | C16: N16 | D16: C16 | E16: Q09472 | F16: EP300
A17: Lib1, Lib2 | B17: 17 | C17: N17 | D17: C17 | E17: Q15910 | F17: EZH2
... A21: Lib1, Lib2 | B21: 22 | C21: N22 | D21: C22 | E21: Q8NFU7 | F21: TET1
A22: Lib1, Lib2 | B22: 23 | C22: N23 | D22: C23 | E22: Q8NFU7 | F22: TET1 | G22: non-recoded
A23: Lib1, Lib2 | B23: 24 | C23: N24 | D23: C24 | E23: Q8NI51 | F23: CTCFL
A24: Lib1, Lib2 | B24: 25 | C24: N25 | D24: C25 | E24: Q8NI51 | F24: CTCFL
A25: Lib1, Lib2 | B25: 26 | C25: N26 | D25: C26 | E25: Q92800 | F25: EZH1
A26: Lib1, Lib2 | B26: 27 | C26: N27 | D26: C27 | E26: Q92800 | F26: EZH1
A27: Lib1, Lib2 | B27: 28 | C27: N28 | D27: C28 | E27: Q96KQ7 | F27: EHMT2 | G27: non-recoded
A28: Lib1, Lib2 | B28: 29 | C28: N29 | D28: C29 | E28: Q9UBL3 | F28: ASH2L
A29: Lib1, Lib2 | B29: 30 | C29: N30 | D29: C30 | E29: Q9Y4C1 | F29: KDM3A | G29: non-recoded
A30: Lib1, Lib2 | B30: 31 | C30: N31 | D30: C31 | E30: Q9Y6K1 | F30: DNMT3A
A31: Lib1, Lib2 | B31: 32 | C31: N32 | D31: C32 | E31: P21506 | F31: Gilbert_Lab_CRISPRi_KRAB
A32: Lib1, Lib2 | B32: 33 | C32: N33 | D32: C33 | E32: Q09472 | F32: Hilton_2015
A33: Lib1, Lib2 | B33: 34 | C33: N34 | D33: C34 | F33: DNMT3A-3L_JKNp112
A34: Lib1, Lib2 | B34: 35 | C34: N35 | D34: C35 | F34: VPR_JKNp64
A35: Lib1, Lib2 | B35: 36 | C35: N36 | D35: C36 | E35: Q8NFU7 | F35: TET1CD_JKNp84 | G35: non-recoded
A36: Lib1, Lib2 | B36: 37 | C36: N37 | D36: C37 | E36: O15550 | F36: KDM6A | G36: non-recoded
A37: Lib1, Lib2 | B37: 38 | C37: N38 | D37: C38 | E37: Q96KQ7 | F37: EHMT2
A38: Lib1, Lib2 | B38: 39 | C38: N39 | D38: C39 | E38: Q9Y4C1 | F38: KDM3A | G38: non-recoded
A39: Lib2 | B39: 40 | C39: N40 | D39: C40 | E39: O60502 | F39: OGA_HUMAN
A40: Lib2 | B40: 41 | C40: N41 | D40: C41 | E40: O60264 | F40: SMCA5_HUMAN
A41: Lib2 | B41: 42 | C41: N42 | D41: C42 | E41: Q8IZD2 | F41: KMT2E_HUMAN
A42: Lib2 | B42: 43 | C42: N43 | D42: C43 | E42: Q9NVD3 | F42: SETD4_HUMAN
A43: Lib2 | B43: 44 | C43: N44 | D43: C44 | E43: O14686 | F43: KMT2D_HUMAN
...
